Requirement already satisfied: fastapi in ./venv/lib/python3.11/site-packages (0.115.11)
Requirement already satisfied: uvicorn in ./venv/lib/python3.11/site-packages (0.34.0)
Requirement already satisfied: pandas in ./venv/lib/python3.11/site-packages (2.2.3)
Requirement already satisfied: numpy in ./venv/lib/python3.11/site-packages (2.2.4)
Requirement already satisfied: scikit-learn in ./venv/lib/python3.11/site-packages (1.6.1)
Requirement already satisfied: xgboost in ./venv/lib/python3.11/site-packages (3.0.0)
Requirement already satisfied: joblib in ./venv/lib/python3.11/site-packages (1.4.2)
Requirement already satisfied: sqlalchemy in ./venv/lib/python3.11/site-packages (2.0.39)
Requirement already satisfied: pymysql in ./venv/lib/python3.11/site-packages (1.1.1)
Requirement already satisfied: apscheduler in ./venv/lib/python3.11/site-packages (3.11.0)
Requirement already satisfied: starlette<0.47.0,>=0.40.0 in ./venv/lib/python3.11/site-packages (from fastapi) (0.46.1)
Requirement already satisfied: pydantic!=1.8,!=1.8.1,!=2.0.0,!=2.0.1,!=2.1.0,<3.0.0,>=1.7.4 in ./venv/lib/python3.11/site-packages (from fastapi) (2.10.6)
Requirement already satisfied: typing-extensions>=4.8.0 in ./venv/lib/python3.11/site-packages (from fastapi) (4.12.2)
Requirement already satisfied: click>=7.0 in ./venv/lib/python3.11/site-packages (from uvicorn) (8.1.8)
Requirement already satisfied: h11>=0.8 in ./venv/lib/python3.11/site-packages (from uvicorn) (0.14.0)
Requirement already satisfied: python-dateutil>=2.8.2 in ./venv/lib/python3.11/site-packages (from pandas) (2.9.0.post0)
Requirement already satisfied: pytz>=2020.1 in ./venv/lib/python3.11/site-packages (from pandas) (2025.1)
Requirement already satisfied: tzdata>=2022.7 in ./venv/lib/python3.11/site-packages (from pandas) (2025.1)
Requirement already satisfied: scipy>=1.6.0 in ./venv/lib/python3.11/site-packages (from scikit-learn) (1.15.2)
Requirement already satisfied: threadpoolctl>=3.1.0 in ./venv/lib/python3.11/site-packages (from scikit-learn) (3.6.0)
Requirement already satisfied: nvidia-nccl-cu12 in ./venv/lib/python3.11/site-packages (from xgboost) (2.26.2)
Requirement already satisfied: greenlet!=0.4.17 in ./venv/lib/python3.11/site-packages (from sqlalchemy) (3.1.1)
Requirement already satisfied: tzlocal>=3.0 in ./venv/lib/python3.11/site-packages (from apscheduler) (5.3.1)
Requirement already satisfied: annotated-types>=0.6.0 in ./venv/lib/python3.11/site-packages (from pydantic!=1.8,!=1.8.1,!=2.0.0,!=2.0.1,!=2.1.0,<3.0.0,>=1.7.4->fastapi) (0.7.0)
Requirement already satisfied: pydantic-core==2.27.2 in ./venv/lib/python3.11/site-packages (from pydantic!=1.8,!=1.8.1,!=2.0.0,!=2.0.1,!=2.1.0,<3.0.0,>=1.7.4->fastapi) (2.27.2)
Requirement already satisfied: six>=1.5 in ./venv/lib/python3.11/site-packages (from python-dateutil>=2.8.2->pandas) (1.17.0)
Requirement already satisfied: anyio<5,>=3.6.2 in ./venv/lib/python3.11/site-packages (from starlette<0.47.0,>=0.40.0->fastapi) (4.9.0)
Requirement already satisfied: idna>=2.8 in ./venv/lib/python3.11/site-packages (from anyio<5,>=3.6.2->starlette<0.47.0,>=0.40.0->fastapi) (3.10)
Requirement already satisfied: sniffio>=1.1 in ./venv/lib/python3.11/site-packages (from anyio<5,>=3.6.2->starlette<0.47.0,>=0.40.0->fastapi) (1.3.1)
Traceback (most recent call last):
  File "/home/usuario/Downloads/inteligenciaartificialexemplo/venv/lib/python3.11/site-packages/pymysql/connections.py", line 649, in connect
    sock = socket.create_connection(
           ^^^^^^^^^^^^^^^^^^^^^^^^^
  File "/usr/lib/python3.11/socket.py", line 827, in create_connection
    for res in getaddrinfo(host, port, 0, SOCK_STREAM):
               ^^^^^^^^^^^^^^^^^^^^^^^^^^^^^^^^^^^^^^^
  File "/usr/lib/python3.11/socket.py", line 962, in getaddrinfo
    for res in _socket.getaddrinfo(host, port, family, type, proto, flags):
               ^^^^^^^^^^^^^^^^^^^^^^^^^^^^^^^^^^^^^^^^^^^^^^^^^^^^^^^^^^^
socket.gaierror: [Errno -2] Name or service not known

During handling of the above exception, another exception occurred:

Traceback (most recent call last):
  File "/home/usuario/Downloads/inteligenciaartificialexemplo/venv/lib/python3.11/site-packages/sqlalchemy/engine/base.py", line 146, in __init__
    self._dbapi_connection = engine.raw_connection()
                             ^^^^^^^^^^^^^^^^^^^^^^^
  File "/home/usuario/Downloads/inteligenciaartificialexemplo/venv/lib/python3.11/site-packages/sqlalchemy/engine/base.py", line 3298, in raw_connection
    return self.pool.connect()
           ^^^^^^^^^^^^^^^^^^^
  File "/home/usuario/Downloads/inteligenciaartificialexemplo/venv/lib/python3.11/site-packages/sqlalchemy/pool/base.py", line 449, in connect
    return _ConnectionFairy._checkout(self)
           ^^^^^^^^^^^^^^^^^^^^^^^^^^^^^^^^
  File "/home/usuario/Downloads/inteligenciaartificialexemplo/venv/lib/python3.11/site-packages/sqlalchemy/pool/base.py", line 1264, in _checkout
    fairy = _ConnectionRecord.checkout(pool)
            ^^^^^^^^^^^^^^^^^^^^^^^^^^^^^^^^
  File "/home/usuario/Downloads/inteligenciaartificialexemplo/venv/lib/python3.11/site-packages/sqlalchemy/pool/base.py", line 713, in checkout
    rec = pool._do_get()
          ^^^^^^^^^^^^^^
  File "/home/usuario/Downloads/inteligenciaartificialexemplo/venv/lib/python3.11/site-packages/sqlalchemy/pool/impl.py", line 179, in _do_get
    with util.safe_reraise():
  File "/home/usuario/Downloads/inteligenciaartificialexemplo/venv/lib/python3.11/site-packages/sqlalchemy/util/langhelpers.py", line 146, in __exit__
    raise exc_value.with_traceback(exc_tb)
  File "/home/usuario/Downloads/inteligenciaartificialexemplo/venv/lib/python3.11/site-packages/sqlalchemy/pool/impl.py", line 177, in _do_get
    return self._create_connection()
           ^^^^^^^^^^^^^^^^^^^^^^^^^
  File "/home/usuario/Downloads/inteligenciaartificialexemplo/venv/lib/python3.11/site-packages/sqlalchemy/pool/base.py", line 390, in _create_connection
    return _ConnectionRecord(self)
           ^^^^^^^^^^^^^^^^^^^^^^^
  File "/home/usuario/Downloads/inteligenciaartificialexemplo/venv/lib/python3.11/site-packages/sqlalchemy/pool/base.py", line 675, in __init__
    self.__connect()
  File "/home/usuario/Downloads/inteligenciaartificialexemplo/venv/lib/python3.11/site-packages/sqlalchemy/pool/base.py", line 901, in __connect
    with util.safe_reraise():
  File "/home/usuario/Downloads/inteligenciaartificialexemplo/venv/lib/python3.11/site-packages/sqlalchemy/util/langhelpers.py", line 146, in __exit__
    raise exc_value.with_traceback(exc_tb)
  File "/home/usuario/Downloads/inteligenciaartificialexemplo/venv/lib/python3.11/site-packages/sqlalchemy/pool/base.py", line 897, in __connect
    self.dbapi_connection = connection = pool._invoke_creator(self)
                                         ^^^^^^^^^^^^^^^^^^^^^^^^^^
  File "/home/usuario/Downloads/inteligenciaartificialexemplo/venv/lib/python3.11/site-packages/sqlalchemy/engine/create.py", line 646, in connect
    return dialect.connect(*cargs, **cparams)
           ^^^^^^^^^^^^^^^^^^^^^^^^^^^^^^^^^^
  File "/home/usuario/Downloads/inteligenciaartificialexemplo/venv/lib/python3.11/site-packages/sqlalchemy/engine/default.py", line 622, in connect
    return self.loaded_dbapi.connect(*cargs, **cparams)
           ^^^^^^^^^^^^^^^^^^^^^^^^^^^^^^^^^^^^^^^^^^^^
  File "/home/usuario/Downloads/inteligenciaartificialexemplo/venv/lib/python3.11/site-packages/pymysql/connections.py", line 361, in __init__
    self.connect()
  File "/home/usuario/Downloads/inteligenciaartificialexemplo/venv/lib/python3.11/site-packages/pymysql/connections.py", line 716, in connect
    raise exc
pymysql.err.OperationalError: (2003, "Can't connect to MySQL server on '(DB_HOST)' ([Errno -2] Name or service not known)")

The above exception was the direct cause of the following exception:

Traceback (most recent call last):
  File "<frozen runpy>", line 198, in _run_module_as_main
  File "<frozen runpy>", line 88, in _run_code
  File "/home/usuario/Downloads/inteligenciaartificialexemplo/app/train_model.py", line 28, in <module>
    treinar_modelo()
  File "/home/usuario/Downloads/inteligenciaartificialexemplo/app/train_model.py", line 8, in treinar_modelo
    dados = carregar_dados()
            ^^^^^^^^^^^^^^^^
  File "/home/usuario/Downloads/inteligenciaartificialexemplo/app/process.py", line 21, in carregar_dados
    dados = pd.read_sql(query, engine)
            ^^^^^^^^^^^^^^^^^^^^^^^^^^
  File "/home/usuario/Downloads/inteligenciaartificialexemplo/venv/lib/python3.11/site-packages/pandas/io/sql.py", line 704, in read_sql
    with pandasSQL_builder(con) as pandas_sql:
         ^^^^^^^^^^^^^^^^^^^^^^
  File "/home/usuario/Downloads/inteligenciaartificialexemplo/venv/lib/python3.11/site-packages/pandas/io/sql.py", line 906, in pandasSQL_builder
    return SQLDatabase(con, schema, need_transaction)
           ^^^^^^^^^^^^^^^^^^^^^^^^^^^^^^^^^^^^^^^^^^
  File "/home/usuario/Downloads/inteligenciaartificialexemplo/venv/lib/python3.11/site-packages/pandas/io/sql.py", line 1636, in __init__
    con = self.exit_stack.enter_context(con.connect())
                                        ^^^^^^^^^^^^^
  File "/home/usuario/Downloads/inteligenciaartificialexemplo/venv/lib/python3.11/site-packages/sqlalchemy/engine/base.py", line 3274, in connect
    return self._connection_cls(self)
           ^^^^^^^^^^^^^^^^^^^^^^^^^^
  File "/home/usuario/Downloads/inteligenciaartificialexemplo/venv/lib/python3.11/site-packages/sqlalchemy/engine/base.py", line 148, in __init__
    Connection._handle_dbapi_exception_noconnection(
  File "/home/usuario/Downloads/inteligenciaartificialexemplo/venv/lib/python3.11/site-packages/sqlalchemy/engine/base.py", line 2439, in _handle_dbapi_exception_noconnection
    raise sqlalchemy_exception.with_traceback(exc_info[2]) from e
  File "/home/usuario/Downloads/inteligenciaartificialexemplo/venv/lib/python3.11/site-packages/sqlalchemy/engine/base.py", line 146, in __init__
    self._dbapi_connection = engine.raw_connection()
                             ^^^^^^^^^^^^^^^^^^^^^^^
  File "/home/usuario/Downloads/inteligenciaartificialexemplo/venv/lib/python3.11/site-packages/sqlalchemy/engine/base.py", line 3298, in raw_connection
    return self.pool.connect()
           ^^^^^^^^^^^^^^^^^^^
  File "/home/usuario/Downloads/inteligenciaartificialexemplo/venv/lib/python3.11/site-packages/sqlalchemy/pool/base.py", line 449, in connect
    return _ConnectionFairy._checkout(self)
           ^^^^^^^^^^^^^^^^^^^^^^^^^^^^^^^^
  File "/home/usuario/Downloads/inteligenciaartificialexemplo/venv/lib/python3.11/site-packages/sqlalchemy/pool/base.py", line 1264, in _checkout
    fairy = _ConnectionRecord.checkout(pool)
            ^^^^^^^^^^^^^^^^^^^^^^^^^^^^^^^^
  File "/home/usuario/Downloads/inteligenciaartificialexemplo/venv/lib/python3.11/site-packages/sqlalchemy/pool/base.py", line 713, in checkout
    rec = pool._do_get()
          ^^^^^^^^^^^^^^
  File "/home/usuario/Downloads/inteligenciaartificialexemplo/venv/lib/python3.11/site-packages/sqlalchemy/pool/impl.py", line 179, in _do_get
    with util.safe_reraise():
  File "/home/usuario/Downloads/inteligenciaartificialexemplo/venv/lib/python3.11/site-packages/sqlalchemy/util/langhelpers.py", line 146, in __exit__
    raise exc_value.with_traceback(exc_tb)
  File "/home/usuario/Downloads/inteligenciaartificialexemplo/venv/lib/python3.11/site-packages/sqlalchemy/pool/impl.py", line 177, in _do_get
    return self._create_connection()
           ^^^^^^^^^^^^^^^^^^^^^^^^^
  File "/home/usuario/Downloads/inteligenciaartificialexemplo/venv/lib/python3.11/site-packages/sqlalchemy/pool/base.py", line 390, in _create_connection
    return _ConnectionRecord(self)
           ^^^^^^^^^^^^^^^^^^^^^^^
  File "/home/usuario/Downloads/inteligenciaartificialexemplo/venv/lib/python3.11/site-packages/sqlalchemy/pool/base.py", line 675, in __init__
    self.__connect()
  File "/home/usuario/Downloads/inteligenciaartificialexemplo/venv/lib/python3.11/site-packages/sqlalchemy/pool/base.py", line 901, in __connect
    with util.safe_reraise():
  File "/home/usuario/Downloads/inteligenciaartificialexemplo/venv/lib/python3.11/site-packages/sqlalchemy/util/langhelpers.py", line 146, in __exit__
    raise exc_value.with_traceback(exc_tb)
  File "/home/usuario/Downloads/inteligenciaartificialexemplo/venv/lib/python3.11/site-packages/sqlalchemy/pool/base.py", line 897, in __connect
    self.dbapi_connection = connection = pool._invoke_creator(self)
                                         ^^^^^^^^^^^^^^^^^^^^^^^^^^
  File "/home/usuario/Downloads/inteligenciaartificialexemplo/venv/lib/python3.11/site-packages/sqlalchemy/engine/create.py", line 646, in connect
    return dialect.connect(*cargs, **cparams)
           ^^^^^^^^^^^^^^^^^^^^^^^^^^^^^^^^^^
  File "/home/usuario/Downloads/inteligenciaartificialexemplo/venv/lib/python3.11/site-packages/sqlalchemy/engine/default.py", line 622, in connect
    return self.loaded_dbapi.connect(*cargs, **cparams)
           ^^^^^^^^^^^^^^^^^^^^^^^^^^^^^^^^^^^^^^^^^^^^
  File "/home/usuario/Downloads/inteligenciaartificialexemplo/venv/lib/python3.11/site-packages/pymysql/connections.py", line 361, in __init__
    self.connect()
  File "/home/usuario/Downloads/inteligenciaartificialexemplo/venv/lib/python3.11/site-packages/pymysql/connections.py", line 716, in connect
    raise exc
sqlalchemy.exc.OperationalError: (pymysql.err.OperationalError) (2003, "Can't connect to MySQL server on '(DB_HOST)' ([Errno -2] Name or service not known)")
(Background on this error at: https://sqlalche.me/e/20/e3q8)
